2025-07-12 16:22:17,989 - errors - ERROR - Error in Query: no such column: updated_at - Context: Failed to get soil samples
2025-07-12 16:22:17,996 - errors - ERROR - Error details: {
  "timestamp": "2025-07-12T16:22:17.995535",
  "run_id": "spatial_processor_test",
  "stage": "Query",
  "context": "Failed to get soil samples",
  "error_type": "OperationalError",
  "error_message": "no such column: updated_at",
  "traceback": "Traceback (most recent call last):\n  File \"E:\\seqana_swe_challenge\\seqana_swe_challenge\\src\\database_manager.py\", line 468, in get_soil_samples\n    cursor.execute(query)\nsqlite3.OperationalError: no such column: updated_at\n"
}
2025-07-12 17:58:20,410 - errors - ERROR - Error in Query: no such column: updated_at - Context: Failed to get soil samples
2025-07-12 17:58:20,411 - errors - ERROR - Error details: {
  "timestamp": "2025-07-12T17:58:20.410132",
  "run_id": "spatial_processor_test",
  "stage": "Query",
  "context": "Failed to get soil samples",
  "error_type": "OperationalError",
  "error_message": "no such column: updated_at",
  "traceback": "Traceback (most recent call last):\n  File \"E:\\seqana_swe_challenge\\seqana_swe_challenge\\src\\database_manager.py\", line 468, in get_soil_samples\n    cursor.execute(query)\nsqlite3.OperationalError: no such column: updated_at\n"
}
